Traceback (most recent call last):
  File "/opt/anaconda3/lib/python3.7/site-packages/jupyter_cache/executors/utils.py", line 56, in single_nb_execution
    record_timing=False,
  File "/opt/anaconda3/lib/python3.7/site-packages/nbclient/client.py", line 1087, in execute
    return NotebookClient(nb=nb, resources=resources, km=km, **kwargs).execute()
  File "/opt/anaconda3/lib/python3.7/site-packages/nbclient/util.py", line 74, in wrapped
    return just_run(coro(*args, **kwargs))
  File "/opt/anaconda3/lib/python3.7/site-packages/nbclient/util.py", line 53, in just_run
    return loop.run_until_complete(coro)
  File "/opt/anaconda3/lib/python3.7/asyncio/base_events.py", line 583, in run_until_complete
    return future.result()
  File "/opt/anaconda3/lib/python3.7/site-packages/nbclient/client.py", line 541, in async_execute
    cell, index, execution_count=self.code_cells_executed + 1
  File "/opt/anaconda3/lib/python3.7/site-packages/nbclient/client.py", line 832, in async_execute_cell
    self._check_raise_for_error(cell, exec_reply)
  File "/opt/anaconda3/lib/python3.7/site-packages/nbclient/client.py", line 740, in _check_raise_for_error
    raise CellExecutionError.from_cell_and_msg(cell, exec_reply['content'])
nbclient.exceptions.CellExecutionError: An error occurred while executing the following cell:
------------------
var='t2'
df_=df[['cancer',var]]

t10=df_[df_.cancer==0][var].values
t11=df_[df_.cancer==1][var].values

#interpolate t10 and t11
mu0, std0 = norm.fit(t10)
mu1, std1 = norm.fit(t11)
x = np.linspace(-5, 5, 100, endpoint=False)
y0 = multivariate_normal.pdf(x, mean=mu0, cov=std0)
y1 = multivariate_normal.pdf(x, mean=mu1, cov=std1)

e=0.00000001
plt.plot(x[y0>y1+e],y0[y0>y1+e],'xg')
a0=trapz(y0[y0>y1+e], x[y0>y1+e])
plt.plot(x[y1>y0+e],y1[y1>y0+e],'ok')
a1=trapz(y1[y1>y0+e], x[y1>y0+e])
print(a0,a1)
print('E=',1-0.5*(a0+a1))
------------------

[0;31m---------------------------------------------------------------------------[0m
[0;31mNameError[0m                                 Traceback (most recent call last)
[0;32m<ipython-input-8-c8bb33347a80>[0m in [0;36m<module>[0;34m[0m
[1;32m      1[0m [0mvar[0m[0;34m=[0m[0;34m't2'[0m[0;34m[0m[0;34m[0m[0m
[0;32m----> 2[0;31m [0mdf_[0m[0;34m=[0m[0mdf[0m[0;34m[[0m[0;34m[[0m[0;34m'cancer'[0m[0;34m,[0m[0mvar[0m[0;34m][0m[0;34m][0m[0;34m[0m[0;34m[0m[0m
[0m[1;32m      3[0m [0;34m[0m[0m
[1;32m      4[0m [0mt10[0m[0;34m=[0m[0mdf_[0m[0;34m[[0m[0mdf_[0m[0;34m.[0m[0mcancer[0m[0;34m==[0m[0;36m0[0m[0;34m][0m[0;34m[[0m[0mvar[0m[0;34m][0m[0;34m.[0m[0mvalues[0m[0;34m[0m[0;34m[0m[0m
[1;32m      5[0m [0mt11[0m[0;34m=[0m[0mdf_[0m[0;34m[[0m[0mdf_[0m[0;34m.[0m[0mcancer[0m[0;34m==[0m[0;36m1[0m[0;34m][0m[0;34m[[0m[0mvar[0m[0;34m][0m[0;34m.[0m[0mvalues[0m[0;34m[0m[0;34m[0m[0m

[0;31mNameError[0m: name 'df' is not defined
NameError: name 'df' is not defined

